Workbook

Sheet README
A1: Global Electricity Transition Analysis, 2015–2025
A2: Data analyst portfolio project · Microsoft Excel · Dataset: Our World in Data – Energy (release of 1 Oct 2026)
A4: PROJECT OBJECTIVE
A5: Goal | B5: Analyse how the world – and India in particular – generated electricity between 2015 and 2025, measure the shift from fossil fuels to renewables, and identify which countries are moving fastest.
A6: Business questions | B6: 1) How has the global electricity mix changed in the last decade? 2) Where does India stand versus the world on renewables and coal? 3) Which large power systems have the highest renewable share today? 4) Which countries added solar + wind the fastest (percentage-point gain)? 5) Which countries remain most dependent on coal?
A7: DATASET
A8: Source | B8: Our World in Data (OWID) – Energy dataset, owid-energy-data.csv, github.com/owid/energy-data (commit dated 1 Oct 2026). OWID compiles electricity data from Ember and the Energy Institute Statistical Review of World Energy. Licence: CC BY 4.0.
A9: Scope used | B9: Years 2015–2025 · 308 raw entities → 212 countries + World aggregate · 2,202 clean rows. Units: TWh (terawatt-hours) for generation, gCO2/kWh for carbon intensity.
A10: Data caveat | B10: 2025 country data is preliminary (90 countries reported vs 210 for 2023). Country rankings therefore default to 2024 (the latest near-complete year); World totals use 2025. Change the year on the Inputs sheet to re-run every analysis.
A11: SHEET GUIDE (work left to right)
A12: Inputs | B12: Yellow cells = parameters you can change (base year, analysis year, minimum system size). Every analysis sheet recalculates from these.
A13: Dashboard | B13: One-page summary: KPI cards and four charts. This is the screenshot for your resume / LinkedIn.
A14: Country_Profile | B14: Interactive: pick any country from the dropdown in cell C4 – the table and both charts update.
A15: Global_Trends | B15: World electricity mix by source, 2015–2025, with shares and year-on-year growth.
A16: Rankings | B16: Top 15 by renewable share, top 15 by solar+wind gain, top 10 most coal-dependent (formula-driven, no manual sorting).
A17: Country_Summary | B17: One row per country: base vs analysis year, change in percentage points, growth rate (CAGR), with conditional formatting.
A18: Clean_Data | B18: Analysis-ready Excel Table (tblEnergy) with calculated columns: fossil, renewable, low-carbon totals, shares, per-capita, data-quality check.
A19: Raw_Data | B19: Untouched extract from the source file (2015–2025, selected columns) – kept so every cleaning step is auditable.
A20: Cleaning_Log | B20: Each cleaning step, the rule applied and rows affected.
A21: Insights | B21: Written findings and recommendations – what you would present to a stakeholder.
A22: Data_Dictionary | B22: Definition, unit and origin of every column.
A23: EXCEL SKILLS DEMONSTRATED
A24: Functions | B24: SUMIFS, COUNTIFS, INDEX/MATCH, LARGE, IFERROR, IF/AND, ISNUMBER, RANK-style tie-breaking, CAGR formula, text keys (country|year lookups).
A25: Features | B25: Excel Tables, data validation dropdowns, conditional formatting (colour scales, data bars, highlight rules), stacked column / bar / line charts, frozen panes, parameter-driven model, KPI dashboard.
A26: Process | B26: Data sourcing → profiling → cleaning with audit log → transformation (calculated columns) → aggregation → ranking → visualisation → insight writing.
A27: PRACTISE THIS (add before interviews)
A28: PivotTable | B28: Click any cell in Clean_Data → Insert → PivotTable → New sheet. Rows: Country · Columns: Year · Values: Renewable_TWh (Sum). Add a Slicer on Entity_Type and set it to "Country". Be ready to explain when you would use a PivotTable vs SUMIFS.
A29: Power Query (optional) | B29: Data → Get Data → From Text/CSV on the original OWID file, and repeat the Cleaning_Log steps as Applied Steps. This makes the refresh fully automatic when OWID publishes new data.
A30: RESUME BULLETS (copy, then adjust)
A31: Bullet 1 | B31: Built an end-to-end Excel analysis of 212 countries' electricity generation (2015–2025, 2,202 records) from Our World in Data, including an auditable cleaning log, calculated metrics and a parameter-driven KPI dashboard.
A32: Bullet 2 | B32: Found global renewables rose from 23.0% to 33.8% of electricity while coal fell from 38.7% to 33.0%; India's renewable share rose from 14.6% to 24.1% as solar output grew 28x.
A33: Bullet 3 | B33: Designed an interactive country profile (dropdown + dynamic charts) and formula-driven rankings using SUMIFS, INDEX/MATCH and LARGE, so the whole workbook recalculates when the analysis year changes.

Sheet Dashboard
A1: GLOBAL ELECTRICITY TRANSITION DASHBOARD · 2015–2025
A2: ="Source: Our World in Data – Energy (Oct 2026 release) · World totals to 2025 · Country comparisons for "&Inputs!$B$6&" (≥ "&Inputs!$B$7&" TWh)" -> Source: Our World in Data – Energy (Oct 2026 release) · World totals to 2025 · Country comparisons for 2024 (≥ 20 TWh)
A4: World renewable share 2025 | D4: World solar + wind share 2025 | G4: World coal share 2025 | J4: Global solar output growth | L4: India renewable share | N4: Countries above RE target
A5: =Global_Trends!K15 -> 0.33760455 | D5: =Global_Trends!L15 -> 0.17284777 | G5: =Global_Trends!M15 -> 0.32957996 | J5: =Global_Trends!H18 -> 10.853639 | L5: =INDEX(Country_Summary!$F$6:$F$217,MATCH("India",Country_Summary!$A$6:$A$217,0)) -> 0.19807809 | N5: =COUNTIFS(Country_Summary!$M$6:$M$217,"Yes",Country_Summary!$F$6:$F$217,">="&Inputs!$B$8) -> 25
A6: =TEXT((Global_Trends!K15-Global_Trends!K5)*100,"+0.0")&" pp since 2015" -> +10.8 pp since 2015 | D6: =TEXT((Global_Trends!L15-Global_Trends!L5)*100,"+0.0")&" pp since 2015" -> +12.8 pp since 2015 | G6: =TEXT((Global_Trends!M15-Global_Trends!M5)*100,"+0.0;-0.0")&" pp since 2015" -> -5.7 pp since 2015 | J6: ="2015 → 2025" -> 2015 → 2025 | L6: ="in "&Inputs!$B$6&" · rank "&Rankings!I25&" of "&Rankings!J25 -> in 2024 · rank 52 of 83 | N6: ="of "&COUNTIF(Country_Summary!$M$6:$M$217,"Yes")&" ranked · target "&TEXT(Inputs!$B$8,"0%") -> of 83 ranked · target 50%
I23: ↑ Line uses the country chosen on Country_Profile (default: India).

Sheet Inputs
A1: Model Inputs
A2: Change the yellow cells only. All analysis sheets recalculate automatically.
A4: Parameter | B4: Value | C4: Notes
A5: Base year | B5: 2015 | C5: Start of the comparison window (2015–2024).
A6: Analysis year | B6: 2024 | C6: Latest year for country comparisons. 2024 is the latest near-complete year; 2025 is preliminary.
A7: Minimum generation (TWh) | B7: 20 | C7: Only countries generating at least this much in the analysis year are ranked – removes tiny island systems that distort shares.
A8: Renewable-share target | B8: 0.5 | C8: Threshold used for the "countries above target" KPI.
A11: Data coverage check (countries with data per year)
A12: Year | B12: Countries reported
A13: 2015 | B13: =COUNTIFS(Clean_Data!$D:$D,A13,Clean_Data!$C:$C,"Country") -> 212
A14: 2016 | B14: =COUNTIFS(Clean_Data!$D:$D,A14,Clean_Data!$C:$C,"Country") -> 212
A15: 2017 | B15: =COUNTIFS(Clean_Data!$D:$D,A15,Clean_Data!$C:$C,"Country") -> 212
A16: 2018 | B16: =COUNTIFS(Clean_Data!$D:$D,A16,Clean_Data!$C:$C,"Country") -> 212
A17: 2019 | B17: =COUNTIFS(Clean_Data!$D:$D,A17,Clean_Data!$C:$C,"Country") -> 212
A18: 2020 | B18: =COUNTIFS(Clean_Data!$D:$D,A18,Clean_Data!$C:$C,"Country") -> 212
A19: 2021 | B19: =COUNTIFS(Clean_Data!$D:$D,A19,Clean_Data!$C:$C,"Country") -> 212
A20: 2022 | B20: =COUNTIFS(Clean_Data!$D:$D,A20,Clean_Data!$C:$C,"Country") -> 212
A21: 2023 | B21: =COUNTIFS(Clean_Data!$D:$D,A21,Clean_Data!$C:$C,"Country") -> 210
A22: 2024 | B22: =COUNTIFS(Clean_Data!$D:$D,A22,Clean_Data!$C:$C,"Country") -> 195
A23: 2025 | B23: =COUNTIFS(Clean_Data!$D:$D,A23,Clean_Data!$C:$C,"Country") -> 90

Sheet Country_Profile
A1: Country Profile
A2: Choose a country in the yellow cell – every number and chart below updates.
G3: Quick stats
B4: Country: | C4: India | G4: Renewable share (latest) | I4: Change since 2015 (pp) | K4: Solar output multiple | M4: Latest year reported
G5: =LOOKUP(2,1/ISNUMBER(K7:K17),K7:K17) -> 0.24067064 | I5: =IF(ISNUMBER(K7),(LOOKUP(2,1/ISNUMBER(K7:K17),K7:K17)-K7)*100,"") -> 9.442018 | K5: =IFERROR(LOOKUP(2,1/ISNUMBER(H7:H17),H7:H17)/H7,"n/a") -> 27.643159 | M5: =LOOKUP(2,1/ISNUMBER(B7:B17),A7:A17) -> 2025
A6: Year | B6: Total TWh | C6: Coal | D6: Gas | E6: Oil | F6: Nuclear | G6: Hydro | H6: Solar | I6: Wind | J6: Bio + Other RE | K6: Renewable Share | L6: Solar+Wind Share | M6: Coal Share | N6: World RE Share | O6: Carbon Int. (g/kWh) | P6: kWh / person
A7: 2015 | B7: =IF(COUNTIFS(Clean_Data!$AB$2:$AB$2203,$C$4&"|"&A7)>0,SUMIFS(Clean_Data!$F$2:$F$2203,Clean_Data!$AB$2:$AB$2203,$C$4&"|"&A7),"") -> 1310.56 | C7: =IF(COUNTIFS(Clean_Data!$AB$2:$AB$2203,$C$4&"|"&A7)>0,SUMIFS(Clean_Data!$G$2:$G$2203,Clean_Data!$AB$2:$AB$2203,$C$4&"|"&A7),"") -> 1006.55 | D7: =IF(COUNTIFS(Clean_Data!$AB$2:$AB$2203,$C$4&"|"&A7)>0,SUMIFS(Clean_Data!$H$2:$H$2203,Clean_Data!$AB$2:$AB$2203,$C$4&"|"&A7),"") -> 64.77 | E7: =IF(COUNTIFS(Clean_Data!$AB$2:$AB$2203,$C$4&"|"&A7)>0,SUMIFS(Clean_Data!$I$2:$I$2203,Clean_Data!$AB$2:$AB$2203,$C$4&"|"&A7),"") -> 9.26 | F7: =IF(COUNTIFS(Clean_Data!$AB$2:$AB$2203,$C$4&"|"&A7)>0,SUMIFS(Clean_Data!$J$2:$J$2203,Clean_Data!$AB$2:$AB$2203,$C$4&"|"&A7),"") -> 38.31 | G7: =IF(COUNTIFS(Clean_Data!$AB$2:$AB$2203,$C$4&"|"&A7)>0,SUMIFS(Clean_Data!$K$2:$K$2203,Clean_Data!$AB$2:$AB$2203,$C$4&"|"&A7),"") -> 133.48 | H7: =IF(COUNTIFS(Clean_Data!$AB$2:$AB$2203,$C$4&"|"&A7)>0,SUMIFS(Clean_Data!$L$2:$L$2203,Clean_Data!$AB$2:$AB$2203,$C$4&"|"&A7),"") -> 7.09 | I7: =IF(COUNTIFS(Clean_Data!$AB$2:$AB$2203,$C$4&"|"&A7)>0,SUMIFS(Clean_Data!$M$2:$M$2203,Clean_Data!$AB$2:$AB$2203,$C$4&"|"&A7),"") -> 32.74 | J7: =IF(COUNTIFS(Clean_Data!$AB$2:$AB$2203,$C$4&"|"&A7)>0,SUMIFS(Clean_Data!$N$2:$N$2203,Clean_Data!$AB$2:$AB$2203,$C$4&"|"&A7)+SUMIFS(Clean_Data!$O$2:$O$2203,Clean_Data!$AB$2:$AB$2203,$C$4&"|"&A7),"") -> 18.36 | K7: =IF(ISNUMBER(B7),(G7+H7+I7+J7)/B7,"") -> 0.14625046 | L7: =IF(ISNUMBER(B7),(H7+I7)/B7,"") -> 0.030391588 | M7: =IF(ISNUMBER(B7),C7/B7,"") -> 0.76803046 | N7: =INDEX(Global_Trends!$K$5:$K$15,MATCH(A7,Global_Trends!$A$5:$A$15,0)) -> 0.22967084 | O7: =IF(COUNTIFS(Clean_Data!$AB$2:$AB$2203,$C$4&"|"&A7,Clean_Data!$P$2:$P$2203,"<>")>0,SUMIFS(Clean_Data!$P$2:$P$2203,Clean_Data!$AB$2:$AB$2203,$C$4&"|"&A7),"") -> 750.6 | P7: =IF(COUNTIFS(Clean_Data!$AB$2:$AB$2203,$C$4&"|"&A7)>0,SUMIFS(Clean_Data!$Z$2:$Z$2203,Clean_Data!$AB$2:$AB$2203,$C$4&"|"&A7),"") -> 986.84927
A8: 2016 | B8: =IF(COUNTIFS(Clean_Data!$AB$2:$AB$2203,$C$4&"|"&A8)>0,SUMIFS(Clean_Data!$F$2:$F$2203,Clean_Data!$AB$2:$AB$2203,$C$4&"|"&A8),"") -> 1394.93 | C8: =IF(COUNTIFS(Clean_Data!$AB$2:$AB$2203,$C$4&"|"&A8)>0,SUMIFS(Clean_Data!$G$2:$G$2203,Clean_Data!$AB$2:$AB$2203,$C$4&"|"&A8),"") -> 1073.6 | D8: =IF(COUNTIFS(Clean_Data!$AB$2:$AB$2203,$C$4&"|"&A8)>0,SUMIFS(Clean_Data!$H$2:$H$2203,Clean_Data!$AB$2:$AB$2203,$C$4&"|"&A8),"") -> 72.62 | E8: =IF(COUNTIFS(Clean_Data!$AB$2:$AB$2203,$C$4&"|"&A8)>0,SUMIFS(Clean_Data!$I$2:$I$2203,Clean_Data!$AB$2:$AB$2203,$C$4&"|"&A8),"") -> 9.41 | F8: =IF(COUNTIFS(Clean_Data!$AB$2:$AB$2203,$C$4&"|"&A8)>0,SUMIFS(Clean_Data!$J$2:$J$2203,Clean_Data!$AB$2:$AB$2203,$C$4&"|"&A8),"") -> 37.9 | G8: =IF(COUNTIFS(Clean_Data!$AB$2:$AB$2203,$C$4&"|"&A8)>0,SUMIFS(Clean_Data!$K$2:$K$2203,Clean_Data!$AB$2:$AB$2203,$C$4&"|"&A8),"") -> 128.55 | H8: =IF(COUNTIFS(Clean_Data!$AB$2:$AB$2203,$C$4&"|"&A8)>0,SUMIFS(Clean_Data!$L$2:$L$2203,Clean_Data!$AB$2:$AB$2203,$C$4&"|"&A8),"") -> 12.2 | I8: =IF(COUNTIFS(Clean_Data!$AB$2:$AB$2203,$C$4&"|"&A8)>0,SUMIFS(Clean_Data!$M$2:$M$2203,Clean_Data!$AB$2:$AB$2203,$C$4&"|"&A8),"") -> 43.45 | J8: =IF(COUNTIFS(Clean_Data!$AB$2:$AB$2203,$C$4&"|"&A8)>0,SUMIFS(Clean_Data!$N$2:$N$2203,Clean_Data!$AB$2:$AB$2203,$C$4&"|"&A8)+SUMIFS(Clean_Data!$O$2:$O$2203,Clean_Data!$AB$2:$AB$2203,$C$4&"|"&A8),"") -> 17.2 | K8: =IF(ISNUMBER(B8),(G8+H8+I8+J8)/B8,"") -> 0.14438 | L8: =IF(ISNUMBER(B8),(H8+I8)/B8,"") -> 0.039894475 | M8: =IF(ISNUMBER(B8),C8/B8,"") -> 0.76964435 | N8: =INDEX(Global_Trends!$K$5:$K$15,MATCH(A8,Global_Trends!$A$5:$A$15,0)) -> 0.23731874 | O8: =IF(COUNTIFS(Clean_Data!$AB$2:$AB$2203,$C$4&"|"&A8,Clean_Data!$P$2:$P$2203,"<>")>0,SUMIFS(Clean_Data!$P$2:$P$2203,Clean_Data!$AB$2:$AB$2203,$C$4&"|"&A8),"") -> 751.9 | P8: =IF(COUNTIFS(Clean_Data!$AB$2:$AB$2203,$C$4&"|"&A8)>0,SUMIFS(Clean_Data!$Z$2:$Z$2203,Clean_Data!$AB$2:$AB$2203,$C$4&"|"&A8),"") -> 1037.9374
A9: 2017 | B9: =IF(COUNTIFS(Clean_Data!$AB$2:$AB$2203,$C$4&"|"&A9)>0,SUMIFS(Clean_Data!$F$2:$F$2203,Clean_Data!$AB$2:$AB$2203,$C$4&"|"&A9),"") -> 1462.39 | C9: =IF(COUNTIFS(Clean_Data!$AB$2:$AB$2203,$C$4&"|"&A9)>0,SUMIFS(Clean_Data!$G$2:$G$2203,Clean_Data!$AB$2:$AB$2203,$C$4&"|"&A9),"") -> 1115.24 | D9: =IF(COUNTIFS(Clean_Data!$AB$2:$AB$2203,$C$4&"|"&A9)>0,SUMIFS(Clean_Data!$H$2:$H$2203,Clean_Data!$AB$2:$AB$2203,$C$4&"|"&A9),"") -> 74.99 | E9: =IF(COUNTIFS(Clean_Data!$AB$2:$AB$2203,$C$4&"|"&A9)>0,SUMIFS(Clean_Data!$I$2:$I$2203,Clean_Data!$AB$2:$AB$2203,$C$4&"|"&A9),"") -> 8.79 | F9: =IF(COUNTIFS(Clean_Data!$AB$2:$AB$2203,$C$4&"|"&A9)>0,SUMIFS(Clean_Data!$J$2:$J$2203,Clean_Data!$AB$2:$AB$2203,$C$4&"|"&A9),"") -> 37.41 | G9: =IF(COUNTIFS(Clean_Data!$AB$2:$AB$2203,$C$4&"|"&A9)>0,SUMIFS(Clean_Data!$K$2:$K$2203,Clean_Data!$AB$2:$AB$2203,$C$4&"|"&A9),"") -> 135.98 | H9: =IF(COUNTIFS(Clean_Data!$AB$2:$AB$2203,$C$4&"|"&A9)>0,SUMIFS(Clean_Data!$L$2:$L$2203,Clean_Data!$AB$2:$AB$2203,$C$4&"|"&A9),"") -> 22.36 | I9: =IF(COUNTIFS(Clean_Data!$AB$2:$AB$2203,$C$4&"|"&A9)>0,SUMIFS(Clean_Data!$M$2:$M$2203,Clean_Data!$AB$2:$AB$2203,$C$4&"|"&A9),"") -> 52.63 | J9: =IF(COUNTIFS(Clean_Data!$AB$2:$AB$2203,$C$4&"|"&A9)>0,SUMIFS(Clean_Data!$N$2:$N$2203,Clean_Data!$AB$2:$AB$2203,$C$4&"|"&A9)+SUMIFS(Clean_Data!$O$2:$O$2203,Clean_Data!$AB$2:$AB$2203,$C$4&"|"&A9),"") -> 14.99 | K9: =IF(ISNUMBER(B9),(G9+H9+I9+J9)/B9,"") -> 0.15451419 | L9: =IF(ISNUMBER(B9),(H9+I9)/B9,"") -> 0.051279071 | M9: =IF(ISNUMBER(B9),C9/B9,"") -> 0.76261462 | N9: =INDEX(Global_Trends!$K$5:$K$15,MATCH(A9,Global_Trends!$A$5:$A$15,0)) -> 0.24465707 | O9: =IF(COUNTIFS(Clean_Data!$AB$2:$AB$2203,$C$4&"|"&A9,Clean_Data!$P$2:$P$2203,"<>")>0,SUMIFS(Clean_Data!$P$2:$P$2203,Clean_Data!$AB$2:$AB$2203,$C$4&"|"&A9),"") -> 743.1 | P9: =IF(COUNTIFS(Clean_Data!$AB$2:$AB$2203,$C$4&"|"&A9)>0,SUMIFS(Clean_Data!$Z$2:$Z$2203,Clean_Data!$AB$2:$AB$2203,$C$4&"|"&A9),"") -> 1075.5577
A10: 2018 | B10: =IF(COUNTIFS(Clean_Data!$AB$2:$AB$2203,$C$4&"|"&A10)>0,SUMIFS(Clean_Data!$F$2:$F$2203,Clean_Data!$AB$2:$AB$2203,$C$4&"|"&A10),"") -> 1571.65 | C10: =IF(COUNTIFS(Clean_Data!$AB$2:$AB$2203,$C$4&"|"&A10)>0,SUMIFS(Clean_Data!$G$2:$G$2203,Clean_Data!$AB$2:$AB$2203,$C$4&"|"&A10),"") -> 1198.86 | D10: =IF(COUNTIFS(Clean_Data!$AB$2:$AB$2203,$C$4&"|"&A10)>0,SUMIFS(Clean_Data!$H$2:$H$2203,Clean_Data!$AB$2:$AB$2203,$C$4&"|"&A10),"") -> 71.26 | E10: =IF(COUNTIFS(Clean_Data!$AB$2:$AB$2203,$C$4&"|"&A10)>0,SUMIFS(Clean_Data!$I$2:$I$2203,Clean_Data!$AB$2:$AB$2203,$C$4&"|"&A10),"") -> 6.4 | F10: =IF(COUNTIFS(Clean_Data!$AB$2:$AB$2203,$C$4&"|"&A10)>0,SUMIFS(Clean_Data!$J$2:$J$2203,Clean_Data!$AB$2:$AB$2203,$C$4&"|"&A10),"") -> 39.05 | G10: =IF(COUNTIFS(Clean_Data!$AB$2:$AB$2203,$C$4&"|"&A10)>0,SUMIFS(Clean_Data!$K$2:$K$2203,Clean_Data!$AB$2:$AB$2203,$C$4&"|"&A10),"") -> 139.92 | H10: =IF(COUNTIFS(Clean_Data!$AB$2:$AB$2203,$C$4&"|"&A10)>0,SUMIFS(Clean_Data!$L$2:$L$2203,Clean_Data!$AB$2:$AB$2203,$C$4&"|"&A10),"") -> 37.45 | I10: =IF(COUNTIFS(Clean_Data!$AB$2:$AB$2203,$C$4&"|"&A10)>0,SUMIFS(Clean_Data!$M$2:$M$2203,Clean_Data!$AB$2:$AB$2203,$C$4&"|"&A10),"") -> 60.31 | J10: =IF(COUNTIFS(Clean_Data!$AB$2:$AB$2203,$C$4&"|"&A10)>0,SUMIFS(Clean_Data!$N$2:$N$2203,Clean_Data!$AB$2:$AB$2203,$C$4&"|"&A10)+SUMIFS(Clean_Data!$O$2:$O$2203,Clean_Data!$AB$2:$AB$2203,$C$4&"|"&A10),"") -> 18.4 | K10: =IF(ISNUMBER(B10),(G10+H10+I10+J10)/B10,"") -> 0.16293704 | L10: =IF(ISNUMBER(B10),(H10+I10)/B10,"") -> 0.062202144 | M10: =IF(ISNUMBER(B10),C10/B10,"") -> 0.76280342 | N10: =INDEX(Global_Trends!$K$5:$K$15,MATCH(A10,Global_Trends!$A$5:$A$15,0)) -> 0.25088713 | O10: =IF(COUNTIFS(Clean_Data!$AB$2:$AB$2203,$C$4&"|"&A10,Clean_Data!$P$2:$P$2203,"<>")>0,SUMIFS(Clean_Data!$P$2:$P$2203,Clean_Data!$AB$2:$AB$2203,$C$4&"|"&A10),"") -> 737.7 | P10: =IF(COUNTIFS(Clean_Data!$AB$2:$AB$2203,$C$4&"|"&A10)>0,SUMIFS(Clean_Data!$Z$2:$Z$2203,Clean_Data!$AB$2:$AB$2203,$C$4&"|"&A10),"") -> 1143.3017
A11: 2019 | B11: =IF(COUNTIFS(Clean_Data!$AB$2:$AB$2203,$C$4&"|"&A11)>0,SUMIFS(Clean_Data!$F$2:$F$2203,Clean_Data!$AB$2:$AB$2203,$C$4&"|"&A11),"") -> 1600.98 | C11: =IF(COUNTIFS(Clean_Data!$AB$2:$AB$2203,$C$4&"|"&A11)>0,SUMIFS(Clean_Data!$G$2:$G$2203,Clean_Data!$AB$2:$AB$2203,$C$4&"|"&A11),"") -> 1198.76 | D11: =IF(COUNTIFS(Clean_Data!$AB$2:$AB$2203,$C$4&"|"&A11)>0,SUMIFS(Clean_Data!$H$2:$H$2203,Clean_Data!$AB$2:$AB$2203,$C$4&"|"&A11),"") -> 71.95 | E11: =IF(COUNTIFS(Clean_Data!$AB$2:$AB$2203,$C$4&"|"&A11)>0,SUMIFS(Clean_Data!$I$2:$I$2203,Clean_Data!$AB$2:$AB$2203,$C$4&"|"&A11),"") -> 3.07 | F11: =IF(COUNTIFS(Clean_Data!$AB$2:$AB$2203,$C$4&"|"&A11)>0,SUMIFS(Clean_Data!$J$2:$J$2203,Clean_Data!$AB$2:$AB$2203,$C$4&"|"&A11),"") -> 45.16 | G11: =IF(COUNTIFS(Clean_Data!$AB$2:$AB$2203,$C$4&"|"&A11)>0,SUMIFS(Clean_Data!$K$2:$K$2203,Clean_Data!$AB$2:$AB$2203,$C$4&"|"&A11),"") -> 162.29 | H11: =IF(COUNTIFS(Clean_Data!$AB$2:$AB$2203,$C$4&"|"&A11)>0,SUMIFS(Clean_Data!$L$2:$L$2203,Clean_Data!$AB$2:$AB$2203,$C$4&"|"&A11),"") -> 37.45 | I11: =IF(COUNTIFS(Clean_Data!$AB$2:$AB$2203,$C$4&"|"&A11)>0,SUMIFS(Clean_Data!$M$2:$M$2203,Clean_Data!$AB$2:$AB$2203,$C$4&"|"&A11),"") -> 63.31 | J11: =IF(COUNTIFS(Clean_Data!$AB$2:$AB$2203,$C$4&"|"&A11)>0,SUMIFS(Clean_Data!$N$2:$N$2203,Clean_Data!$AB$2:$AB$2203,$C$4&"|"&A11)+SUMIFS(Clean_Data!$O$2:$O$2203,Clean_Data!$AB$2:$AB$2203,$C$4&"|"&A11),"") -> 18.99 | K11: =IF(ISNUMBER(B11),(G11+H11+I11+J11)/B11,"") -> 0.1761671 | L11: =IF(ISNUMBER(B11),(H11+I11)/B11,"") -> 0.062936451 | M11: =IF(ISNUMBER(B11),C11/B11,"") -> 0.74876638 | N11: =INDEX(Global_Trends!$K$5:$K$15,MATCH(A11,Global_Trends!$A$5:$A$15,0)) -> 0.26071484 | O11: =IF(COUNTIFS(Clean_Data!$AB$2:$AB$2203,$C$4&"|"&A11,Clean_Data!$P$2:$P$2203,"<>")>0,SUMIFS(Clean_Data!$P$2:$P$2203,Clean_Data!$AB$2:$AB$2203,$C$4&"|"&A11),"") -> 722.7 | P11: =IF(COUNTIFS(Clean_Data!$AB$2:$AB$2203,$C$4&"|"&A11)>0,SUMIFS(Clean_Data!$Z$2:$Z$2203,Clean_Data!$AB$2:$AB$2203,$C$4&"|"&A11),"") -> 1152.5882
A12: 2020 | B12: =IF(COUNTIFS(Clean_Data!$AB$2:$AB$2203,$C$4&"|"&A12)>0,SUMIFS(Clean_Data!$F$2:$F$2203,Clean_Data!$AB$2:$AB$2203,$C$4&"|"&A12),"") -> 1563.43 | C12: =IF(COUNTIFS(Clean_Data!$AB$2:$AB$2203,$C$4&"|"&A12)>0,SUMIFS(Clean_Data!$G$2:$G$2203,Clean_Data!$AB$2:$AB$2203,$C$4&"|"&A12),"") -> 1143.78 | D12: =IF(COUNTIFS(Clean_Data!$AB$2:$AB$2203,$C$4&"|"&A12)>0,SUMIFS(Clean_Data!$H$2:$H$2203,Clean_Data!$AB$2:$AB$2203,$C$4&"|"&A12),"") -> 74.79 | E12: =IF(COUNTIFS(Clean_Data!$AB$2:$AB$2203,$C$4&"|"&A12)>0,SUMIFS(Clean_Data!$I$2:$I$2203,Clean_Data!$AB$2:$AB$2203,$C$4&"|"&A12),"") -> 3.09 | F12: =IF(COUNTIFS(Clean_Data!$AB$2:$AB$2203,$C$4&"|"&A12)>0,SUMIFS(Clean_Data!$J$2:$J$2203,Clean_Data!$AB$2:$AB$2203,$C$4&"|"&A12),"") -> 44.61 | G12: =IF(COUNTIFS(Clean_Data!$AB$2:$AB$2203,$C$4&"|"&A12)>0,SUMIFS(Clean_Data!$K$2:$K$2203,Clean_Data!$AB$2:$AB$2203,$C$4&"|"&A12),"") -> 163.94 | H12: =IF(COUNTIFS(Clean_Data!$AB$2:$AB$2203,$C$4&"|"&A12)>0,SUMIFS(Clean_Data!$L$2:$L$2203,Clean_Data!$AB$2:$AB$2203,$C$4&"|"&A12),"") -> 52.91 | I12: =IF(COUNTIFS(Clean_Data!$AB$2:$AB$2203,$C$4&"|"&A12)>0,SUMIFS(Clean_Data!$M$2:$M$2203,Clean_Data!$AB$2:$AB$2203,$C$4&"|"&A12),"") -> 60.43 | J12: =IF(COUNTIFS(Clean_Data!$AB$2:$AB$2203,$C$4&"|"&A12)>0,SUMIFS(Clean_Data!$N$2:$N$2203,Clean_Data!$AB$2:$AB$2203,$C$4&"|"&A12)+SUMIFS(Clean_Data!$O$2:$O$2203,Clean_Data!$AB$2:$AB$2203,$C$4&"|"&A12),"") -> 19.88 | K12: =IF(ISNUMBER(B12),(G12+H12+I12+J12)/B12,"") -> 0.19006927 | L12: =IF(ISNUMBER(B12),(H12+I12)/B12,"") -> 0.072494451 | M12: =IF(ISNUMBER(B12),C12/B12,"") -> 0.73158376 | N12: =INDEX(Global_Trends!$K$5:$K$15,MATCH(A12,Global_Trends!$A$5:$A$15,0)) -> 0.27987377 | O12: =IF(COUNTIFS(Clean_Data!$AB$2:$AB$2203,$C$4&"|"&A12,Clean_Data!$P$2:$P$2203,"<>")>0,SUMIFS(Clean_Data!$P$2:$P$2203,Clean_Data!$AB$2:$AB$2203,$C$4&"|"&A12),"") -> 709.1 | P12: =IF(COUNTIFS(Clean_Data!$AB$2:$AB$2203,$C$4&"|"&A12)>0,SUMIFS(Clean_Data!$Z$2:$Z$2203,Clean_Data!$AB$2:$AB$2203,$C$4&"|"&A12),"") -> 1114.6516
A13: 2021 | B13: =IF(COUNTIFS(Clean_Data!$AB$2:$AB$2203,$C$4&"|"&A13)>0,SUMIFS(Clean_Data!$F$2:$F$2203,Clean_Data!$AB$2:$AB$2203,$C$4&"|"&A13),"") -> 1678.72 | C13: =IF(COUNTIFS(Clean_Data!$AB$2:$AB$2203,$C$4&"|"&A13)>0,SUMIFS(Clean_Data!$G$2:$G$2203,Clean_Data!$AB$2:$AB$2203,$C$4&"|"&A13),"") -> 1255.56 | D13: =IF(COUNTIFS(Clean_Data!$AB$2:$AB$2203,$C$4&"|"&A13)>0,SUMIFS(Clean_Data!$H$2:$H$2203,Clean_Data!$AB$2:$AB$2203,$C$4&"|"&A13),"") -> 60.4 | E13: =IF(COUNTIFS(Clean_Data!$AB$2:$AB$2203,$C$4&"|"&A13)>0,SUMIFS(Clean_Data!$I$2:$I$2203,Clean_Data!$AB$2:$AB$2203,$C$4&"|"&A13),"") -> 3.39 | F13: =IF(COUNTIFS(Clean_Data!$AB$2:$AB$2203,$C$4&"|"&A13)>0,SUMIFS(Clean_Data!$J$2:$J$2203,Clean_Data!$AB$2:$AB$2203,$C$4&"|"&A13),"") -> 43.92 | G13: =IF(COUNTIFS(Clean_Data!$AB$2:$AB$2203,$C$4&"|"&A13)>0,SUMIFS(Clean_Data!$K$2:$K$2203,Clean_Data!$AB$2:$AB$2203,$C$4&"|"&A13),"") -> 160.57 | H13: =IF(COUNTIFS(Clean_Data!$AB$2:$AB$2203,$C$4&"|"&A13)>0,SUMIFS(Clean_Data!$L$2:$L$2203,Clean_Data!$AB$2:$AB$2203,$C$4&"|"&A13),"") -> 65.59 | I13: =IF(COUNTIFS(Clean_Data!$AB$2:$AB$2203,$C$4&"|"&A13)>0,SUMIFS(Clean_Data!$M$2:$M$2203,Clean_Data!$AB$2:$AB$2203,$C$4&"|"&A13),"") -> 68.09 | J13: =IF(COUNTIFS(Clean_Data!$AB$2:$AB$2203,$C$4&"|"&A13)>0,SUMIFS(Clean_Data!$N$2:$N$2203,Clean_Data!$AB$2:$AB$2203,$C$4&"|"&A13)+SUMIFS(Clean_Data!$O$2:$O$2203,Clean_Data!$AB$2:$AB$2203,$C$4&"|"&A13),"") -> 21.2 | K13: =IF(ISNUMBER(B13),(G13+H13+I13+J13)/B13,"") -> 0.18791103 | L13: =IF(ISNUMBER(B13),(H13+I13)/B13,"") -> 0.079632101 | M13: =IF(ISNUMBER(B13),C13/B13,"") -> 0.74792699 | N13: =INDEX(Global_Trends!$K$5:$K$15,MATCH(A13,Global_Trends!$A$5:$A$15,0)) -> 0.28101633 | O13: =IF(COUNTIFS(Clean_Data!$AB$2:$AB$2203,$C$4&"|"&A13,Clean_Data!$P$2:$P$2203,"<>")>0,SUMIFS(Clean_Data!$P$2:$P$2203,Clean_Data!$AB$2:$AB$2203,$C$4&"|"&A13),"") -> 715.3 | P13: =IF(COUNTIFS(Clean_Data!$AB$2:$AB$2203,$C$4&"|"&A13)>0,SUMIFS(Clean_Data!$Z$2:$Z$2203,Clean_Data!$AB$2:$AB$2203,$C$4&"|"&A13),"") -> 1187.0424
A14: 2022 | B14: =IF(COUNTIFS(Clean_Data!$AB$2:$AB$2203,$C$4&"|"&A14)>0,SUMIFS(Clean_Data!$F$2:$F$2203,Clean_Data!$AB$2:$AB$2203,$C$4&"|"&A14),"") -> 1804.61 | C14: =IF(COUNTIFS(Clean_Data!$AB$2:$AB$2203,$C$4&"|"&A14)>0,SUMIFS(Clean_Data!$G$2:$G$2203,Clean_Data!$AB$2:$AB$2203,$C$4&"|"&A14),"") -> 1344.42 | D14: =IF(COUNTIFS(Clean_Data!$AB$2:$AB$2203,$C$4&"|"&A14)>0,SUMIFS(Clean_Data!$H$2:$H$2203,Clean_Data!$AB$2:$AB$2203,$C$4&"|"&A14),"") -> 46.17 | E14: =IF(COUNTIFS(Clean_Data!$AB$2:$AB$2203,$C$4&"|"&A14)>0,SUMIFS(Clean_Data!$I$2:$I$2203,Clean_Data!$AB$2:$AB$2203,$C$4&"|"&A14),"") -> 3.48 | F14: =IF(COUNTIFS(Clean_Data!$AB$2:$AB$2203,$C$4&"|"&A14)>0,SUMIFS(Clean_Data!$J$2:$J$2203,Clean_Data!$AB$2:$AB$2203,$C$4&"|"&A14),"") -> 46.19 | G14: =IF(COUNTIFS(Clean_Data!$AB$2:$AB$2203,$C$4&"|"&A14)>0,SUMIFS(Clean_Data!$K$2:$K$2203,Clean_Data!$AB$2:$AB$2203,$C$4&"|"&A14),"") -> 175.09 | H14: =IF(COUNTIFS(Clean_Data!$AB$2:$AB$2203,$C$4&"|"&A14)>0,SUMIFS(Clean_Data!$L$2:$L$2203,Clean_Data!$AB$2:$AB$2203,$C$4&"|"&A14),"") -> 95.92 | I14: =IF(COUNTIFS(Clean_Data!$AB$2:$AB$2203,$C$4&"|"&A14)>0,SUMIFS(Clean_Data!$M$2:$M$2203,Clean_Data!$AB$2:$AB$2203,$C$4&"|"&A14),"") -> 70.05 | J14: =IF(COUNTIFS(Clean_Data!$AB$2:$AB$2203,$C$4&"|"&A14)>0,SUMIFS(Clean_Data!$N$2:$N$2203,Clean_Data!$AB$2:$AB$2203,$C$4&"|"&A14)+SUMIFS(Clean_Data!$O$2:$O$2203,Clean_Data!$AB$2:$AB$2203,$C$4&"|"&A14),"") -> 23.29 | K14: =IF(ISNUMBER(B14),(G14+H14+I14+J14)/B14,"") -> 0.20189958 | L14: =IF(ISNUMBER(B14),(H14+I14)/B14,"") -> 0.09197001 | M14: =IF(ISNUMBER(B14),C14/B14,"") -> 0.74499199 | N14: =INDEX(Global_Trends!$K$5:$K$15,MATCH(A14,Global_Trends!$A$5:$A$15,0)) -> 0.29469745 | O14: =IF(COUNTIFS(Clean_Data!$AB$2:$AB$2203,$C$4&"|"&A14,Clean_Data!$P$2:$P$2203,"<>")>0,SUMIFS(Clean_Data!$P$2:$P$2203,Clean_Data!$AB$2:$AB$2203,$C$4&"|"&A14),"") -> 705.8 | P14: =IF(COUNTIFS(Clean_Data!$AB$2:$AB$2203,$C$4&"|"&A14)>0,SUMIFS(Clean_Data!$Z$2:$Z$2203,Clean_Data!$AB$2:$AB$2203,$C$4&"|"&A14),"") -> 1266.017
A15: 2023 | B15: =IF(COUNTIFS(Clean_Data!$AB$2:$AB$2203,$C$4&"|"&A15)>0,SUMIFS(Clean_Data!$F$2:$F$2203,Clean_Data!$AB$2:$AB$2203,$C$4&"|"&A15),"") -> 1918.26 | C15: =IF(COUNTIFS(Clean_Data!$AB$2:$AB$2203,$C$4&"|"&A15)>0,SUMIFS(Clean_Data!$G$2:$G$2203,Clean_Data!$AB$2:$AB$2203,$C$4&"|"&A15),"") -> 1445.44 | D15: =IF(COUNTIFS(Clean_Data!$AB$2:$AB$2203,$C$4&"|"&A15)>0,SUMIFS(Clean_Data!$H$2:$H$2203,Clean_Data!$AB$2:$AB$2203,$C$4&"|"&A15),"") -> 50.8 | E15: =IF(COUNTIFS(Clean_Data!$AB$2:$AB$2203,$C$4&"|"&A15)>0,SUMIFS(Clean_Data!$I$2:$I$2203,Clean_Data!$AB$2:$AB$2203,$C$4&"|"&A15),"") -> 3.85 | F15: =IF(COUNTIFS(Clean_Data!$AB$2:$AB$2203,$C$4&"|"&A15)>0,SUMIFS(Clean_Data!$J$2:$J$2203,Clean_Data!$AB$2:$AB$2203,$C$4&"|"&A15),"") -> 48.2 | G15: =IF(COUNTIFS(Clean_Data!$AB$2:$AB$2203,$C$4&"|"&A15)>0,SUMIFS(Clean_Data!$K$2:$K$2203,Clean_Data!$AB$2:$AB$2203,$C$4&"|"&A15),"") -> 149.43 | H15: =IF(COUNTIFS(Clean_Data!$AB$2:$AB$2203,$C$4&"|"&A15)>0,SUMIFS(Clean_Data!$L$2:$L$2203,Clean_Data!$AB$2:$AB$2203,$C$4&"|"&A15),"") -> 115.42 | I15: =IF(COUNTIFS(Clean_Data!$AB$2:$AB$2203,$C$4&"|"&A15)>0,SUMIFS(Clean_Data!$M$2:$M$2203,Clean_Data!$AB$2:$AB$2203,$C$4&"|"&A15),"") -> 82.11 | J15: =IF(COUNTIFS(Clean_Data!$AB$2:$AB$2203,$C$4&"|"&A15)>0,SUMIFS(Clean_Data!$N$2:$N$2203,Clean_Data!$AB$2:$AB$2203,$C$4&"|"&A15)+SUMIFS(Clean_Data!$O$2:$O$2203,Clean_Data!$AB$2:$AB$2203,$C$4&"|"&A15),"") -> 23.01 | K15: =IF(ISNUMBER(B15),(G15+H15+I15+J15)/B15,"") -> 0.19286749 | L15: =IF(ISNUMBER(B15),(H15+I15)/B15,"") -> 0.10297353 | M15: =IF(ISNUMBER(B15),C15/B15,"") -> 0.75351621 | N15: =INDEX(Global_Trends!$K$5:$K$15,MATCH(A15,Global_Trends!$A$5:$A$15,0)) -> 0.30323098 | O15: =IF(COUNTIFS(Clean_Data!$AB$2:$AB$2203,$C$4&"|"&A15,Clean_Data!$P$2:$P$2203,"<>")>0,SUMIFS(Clean_Data!$P$2:$P$2203,Clean_Data!$AB$2:$AB$2203,$C$4&"|"&A15),"") -> 713.4 | P15: =IF(COUNTIFS(Clean_Data!$AB$2:$AB$2203,$C$4&"|"&A15)>0,SUMIFS(Clean_Data!$Z$2:$Z$2203,Clean_Data!$AB$2:$AB$2203,$C$4&"|"&A15),"") -> 1333.9132
A16: 2024 | B16: =IF(COUNTIFS(Clean_Data!$AB$2:$AB$2203,$C$4&"|"&A16)>0,SUMIFS(Clean_Data!$F$2:$F$2203,Clean_Data!$AB$2:$AB$2203,$C$4&"|"&A16),"") -> 2036.52 | C16: =IF(COUNTIFS(Clean_Data!$AB$2:$AB$2203,$C$4&"|"&A16)>0,SUMIFS(Clean_Data!$G$2:$G$2203,Clean_Data!$AB$2:$AB$2203,$C$4&"|"&A16),"") -> 1517.9 | D16: =IF(COUNTIFS(Clean_Data!$AB$2:$AB$2203,$C$4&"|"&A16)>0,SUMIFS(Clean_Data!$H$2:$H$2203,Clean_Data!$AB$2:$AB$2203,$C$4&"|"&A16),"") -> 56.44 | E16: =IF(COUNTIFS(Clean_Data!$AB$2:$AB$2203,$C$4&"|"&A16)>0,SUMIFS(Clean_Data!$I$2:$I$2203,Clean_Data!$AB$2:$AB$2203,$C$4&"|"&A16),"") -> 4.09 | F16: =IF(COUNTIFS(Clean_Data!$AB$2:$AB$2203,$C$4&"|"&A16)>0,SUMIFS(Clean_Data!$J$2:$J$2203,Clean_Data!$AB$2:$AB$2203,$C$4&"|"&A16),"") -> 54.7 | G16: =IF(COUNTIFS(Clean_Data!$AB$2:$AB$2203,$C$4&"|"&A16)>0,SUMIFS(Clean_Data!$K$2:$K$2203,Clean_Data!$AB$2:$AB$2203,$C$4&"|"&A16),"") -> 156.53 | H16: =IF(COUNTIFS(Clean_Data!$AB$2:$AB$2203,$C$4&"|"&A16)>0,SUMIFS(Clean_Data!$L$2:$L$2203,Clean_Data!$AB$2:$AB$2203,$C$4&"|"&A16),"") -> 143.07 | I16: =IF(COUNTIFS(Clean_Data!$AB$2:$AB$2203,$C$4&"|"&A16)>0,SUMIFS(Clean_Data!$M$2:$M$2203,Clean_Data!$AB$2:$AB$2203,$C$4&"|"&A16),"") -> 81.54 | J16: =IF(COUNTIFS(Clean_Data!$AB$2:$AB$2203,$C$4&"|"&A16)>0,SUMIFS(Clean_Data!$N$2:$N$2203,Clean_Data!$AB$2:$AB$2203,$C$4&"|"&A16)+SUMIFS(Clean_Data!$O$2:$O$2203,Clean_Data!$AB$2:$AB$2203,$C$4&"|"&A16),"") -> 22.25 | K16: =IF(ISNUMBER(B16),(G16+H16+I16+J16)/B16,"") -> 0.19807809 | L16: =IF(ISNUMBER(B16),(H16+I16)/B16,"") -> 0.11029108 | M16: =IF(ISNUMBER(B16),C16/B16,"") -> 0.74534009 | N16: =INDEX(Global_Trends!$K$5:$K$15,MATCH(A16,Global_Trends!$A$5:$A$15,0)) -> 0.31935133 | O16: =IF(COUNTIFS(Clean_Data!$AB$2:$AB$2203,$C$4&"|"&A16,Clean_Data!$P$2:$P$2203,"<>")>0,SUMIFS(Clean_Data!$P$2:$P$2203,Clean_Data!$AB$2:$AB$2203,$C$4&"|"&A16),"") -> 705.4 | P16: =IF(COUNTIFS(Clean_Data!$AB$2:$AB$2203,$C$4&"|"&A16)>0,SUMIFS(Clean_Data!$Z$2:$Z$2203,Clean_Data!$AB$2:$AB$2203,$C$4&"|"&A16),"") -> 1403.5907
A17: 2025 | B17: =IF(COUNTIFS(Clean_Data!$AB$2:$AB$2203,$C$4&"|"&A17)>0,SUMIFS(Clean_Data!$F$2:$F$2203,Clean_Data!$AB$2:$AB$2203,$C$4&"|"&A17),"") -> 2081.6 | C17: =IF(COUNTIFS(Clean_Data!$AB$2:$AB$2203,$C$4&"|"&A17)>0,SUMIFS(Clean_Data!$G$2:$G$2203,Clean_Data!$AB$2:$AB$2203,$C$4&"|"&A17),"") -> 1474.15 | D17: =IF(COUNTIFS(Clean_Data!$AB$2:$AB$2203,$C$4&"|"&A17)>0,SUMIFS(Clean_Data!$H$2:$H$2203,Clean_Data!$AB$2:$AB$2203,$C$4&"|"&A17),"") -> 48.54 | E17: =IF(COUNTIFS(Clean_Data!$AB$2:$AB$2203,$C$4&"|"&A17)>0,SUMIFS(Clean_Data!$I$2:$I$2203,Clean_Data!$AB$2:$AB$2203,$C$4&"|"&A17),"") -> 4.1 | F17: =IF(COUNTIFS(Clean_Data!$AB$2:$AB$2203,$C$4&"|"&A17)>0,SUMIFS(Clean_Data!$J$2:$J$2203,Clean_Data!$AB$2:$AB$2203,$C$4&"|"&A17),"") -> 53.83 | G17: =IF(COUNTIFS(Clean_Data!$AB$2:$AB$2203,$C$4&"|"&A17)>0,SUMIFS(Clean_Data!$K$2:$K$2203,Clean_Data!$AB$2:$AB$2203,$C$4&"|"&A17),"") -> 177.97 | H17: =IF(COUNTIFS(Clean_Data!$AB$2:$AB$2203,$C$4&"|"&A17)>0,SUMIFS(Clean_Data!$L$2:$L$2203,Clean_Data!$AB$2:$AB$2203,$C$4&"|"&A17),"") -> 195.99 | I17: =IF(COUNTIFS(Clean_Data!$AB$2:$AB$2203,$C$4&"|"&A17)>0,SUMIFS(Clean_Data!$M$2:$M$2203,Clean_Data!$AB$2:$AB$2203,$C$4&"|"&A17),"") -> 103.98 | J17: =IF(COUNTIFS(Clean_Data!$AB$2:$AB$2203,$C$4&"|"&A17)>0,SUMIFS(Clean_Data!$N$2:$N$2203,Clean_Data!$AB$2:$AB$2203,$C$4&"|"&A17)+SUMIFS(Clean_Data!$O$2:$O$2203,Clean_Data!$AB$2:$AB$2203,$C$4&"|"&A17),"") -> 23.04 | K17: =IF(ISNUMBER(B17),(G17+H17+I17+J17)/B17,"") -> 0.24067064 | L17: =IF(ISNUMBER(B17),(H17+I17)/B17,"") -> 0.1441055 | M17: =IF(ISNUMBER(B17),C17/B17,"") -> 0.70818121 | N17: =INDEX(Global_Trends!$K$5:$K$15,MATCH(A17,Global_Trends!$A$5:$A$15,0)) -> 0.33760455 | O17: =IF(COUNTIFS(Clean_Data!$AB$2:$AB$2203,$C$4&"|"&A17,Clean_Data!$P$2:$P$2203,"<>")>0,SUMIFS(Clean_Data!$P$2:$P$2203,Clean_Data!$AB$2:$AB$2203,$C$4&"|"&A17),"") -> 670.1 | P17: =IF(COUNTIFS(Clean_Data!$AB$2:$AB$2203,$C$4&"|"&A17)>0,SUMIFS(Clean_Data!$Z$2:$Z$2203,Clean_Data!$AB$2:$AB$2203,$C$4&"|"&A17),"") -> 1421.9885

Sheet Global_Trends
A1: Global Electricity Mix, 2015–2025 (World aggregate)
A2: Source: Clean_Data rows where Entity_Type = "World". TWh unless stated.
A4: Year | B4: Total TWh | C4: Coal | D4: Gas | E4: Oil | F4: Nuclear | G4: Hydro | H4: Solar | I4: Wind | J4: Bio + Other RE | K4: Renewable Share | L4: Solar+Wind Share | M4: Coal Share | N4: Fossil Share | O4: Total YoY Growth | P4: Solar YoY Growth
A5: 2015 | B5: =SUMIFS(Clean_Data!$F$2:$F$2203,Clean_Data!$AB$2:$AB$2203,"World|"&A5) -> 24002.35 | C5: =SUMIFS(Clean_Data!$G$2:$G$2203,Clean_Data!$AB$2:$AB$2203,"World|"&A5) -> 9283.61 | D5: =SUMIFS(Clean_Data!$H$2:$H$2203,Clean_Data!$AB$2:$AB$2203,"World|"&A5) -> 5539.88 | E5: =SUMIFS(Clean_Data!$I$2:$I$2203,Clean_Data!$AB$2:$AB$2203,"World|"&A5) -> 1133.29 | F5: =SUMIFS(Clean_Data!$J$2:$J$2203,Clean_Data!$AB$2:$AB$2203,"World|"&A5) -> 2532.93 | G5: =SUMIFS(Clean_Data!$K$2:$K$2203,Clean_Data!$AB$2:$AB$2203,"World|"&A5) -> 3882.13 | H5: =SUMIFS(Clean_Data!$L$2:$L$2203,Clean_Data!$AB$2:$AB$2203,"World|"&A5) -> 256.01 | I5: =SUMIFS(Clean_Data!$M$2:$M$2203,Clean_Data!$AB$2:$AB$2203,"World|"&A5) -> 829.63 | J5: =SUMIFS(Clean_Data!$N$2:$N$2203,Clean_Data!$AB$2:$AB$2203,"World|"&A5)+SUMIFS(Clean_Data!$O$2:$O$2203,Clean_Data!$AB$2:$AB$2203,"World|"&A5) -> 544.87 | K5: =(G5+H5+I5+J5)/B5 -> 0.22967084 | L5: =(H5+I5)/B5 -> 0.045230571 | M5: =C5/B5 -> 0.38677921 | N5: =(C5+D5+E5)/B5 -> 0.66480074 | O5: ="" | P5: =""
A6: 2016 | B6: =SUMIFS(Clean_Data!$F$2:$F$2203,Clean_Data!$AB$2:$AB$2203,"World|"&A6) -> 24694.51 | C6: =SUMIFS(Clean_Data!$G$2:$G$2203,Clean_Data!$AB$2:$AB$2203,"World|"&A6) -> 9327.96 | D6: =SUMIFS(Clean_Data!$H$2:$H$2203,Clean_Data!$AB$2:$AB$2203,"World|"&A6) -> 5849.92 | E6: =SUMIFS(Clean_Data!$I$2:$I$2203,Clean_Data!$AB$2:$AB$2203,"World|"&A6) -> 1085.11 | F6: =SUMIFS(Clean_Data!$J$2:$J$2203,Clean_Data!$AB$2:$AB$2203,"World|"&A6) -> 2571.05 | G6: =SUMIFS(Clean_Data!$K$2:$K$2203,Clean_Data!$AB$2:$AB$2203,"World|"&A6) -> 4014.75 | H6: =SUMIFS(Clean_Data!$L$2:$L$2203,Clean_Data!$AB$2:$AB$2203,"World|"&A6) -> 327.47 | I6: =SUMIFS(Clean_Data!$M$2:$M$2203,Clean_Data!$AB$2:$AB$2203,"World|"&A6) -> 960.3 | J6: =SUMIFS(Clean_Data!$N$2:$N$2203,Clean_Data!$AB$2:$AB$2203,"World|"&A6)+SUMIFS(Clean_Data!$O$2:$O$2203,Clean_Data!$AB$2:$AB$2203,"World|"&A6) -> 557.95 | K6: =(G6+H6+I6+J6)/B6 -> 0.23731874 | L6: =(H6+I6)/B6 -> 0.052148028 | M6: =C6/B6 -> 0.37773416 | N6: =(C6+D6+E6)/B6 -> 0.65856703 | O6: =B6/B5-1 -> 0.028837176 | P6: =H6/H5-1 -> 0.27912972
A7: 2017 | B7: =SUMIFS(Clean_Data!$F$2:$F$2203,Clean_Data!$AB$2:$AB$2203,"World|"&A7) -> 25441.039 | C7: =SUMIFS(Clean_Data!$G$2:$G$2203,Clean_Data!$AB$2:$AB$2203,"World|"&A7) -> 9655.05 | D7: =SUMIFS(Clean_Data!$H$2:$H$2203,Clean_Data!$AB$2:$AB$2203,"World|"&A7) -> 5973.6 | E7: =SUMIFS(Clean_Data!$I$2:$I$2203,Clean_Data!$AB$2:$AB$2203,"World|"&A7) -> 993.83 | F7: =SUMIFS(Clean_Data!$J$2:$J$2203,Clean_Data!$AB$2:$AB$2203,"World|"&A7) -> 2594.23 | G7: =SUMIFS(Clean_Data!$K$2:$K$2203,Clean_Data!$AB$2:$AB$2203,"World|"&A7) -> 4054.03 | H7: =SUMIFS(Clean_Data!$L$2:$L$2203,Clean_Data!$AB$2:$AB$2203,"World|"&A7) -> 444.65 | I7: =SUMIFS(Clean_Data!$M$2:$M$2203,Clean_Data!$AB$2:$AB$2203,"World|"&A7) -> 1139.44 | J7: =SUMIFS(Clean_Data!$N$2:$N$2203,Clean_Data!$AB$2:$AB$2203,"World|"&A7)+SUMIFS(Clean_Data!$O$2:$O$2203,Clean_Data!$AB$2:$AB$2203,"World|"&A7) -> 586.21 | K7: =(G7+H7+I7+J7)/B7 -> 0.24465707 | L7: =(H7+I7)/B7 -> 0.062265146 | M7: =C7/B7 -> 0.37950691 | N7: =(C7+D7+E7)/B7 -> 0.65337269 | O7: =B7/B6-1 -> 0.030230565 | P7: =H7/H6-1 -> 0.35783431
A8: 2018 | B8: =SUMIFS(Clean_Data!$F$2:$F$2203,Clean_Data!$AB$2:$AB$2203,"World|"&A8) -> 26464.49 | C8: =SUMIFS(Clean_Data!$G$2:$G$2203,Clean_Data!$AB$2:$AB$2203,"World|"&A8) -> 10033.03 | D8: =SUMIFS(Clean_Data!$H$2:$H$2203,Clean_Data!$AB$2:$AB$2203,"World|"&A8) -> 6224.56 | E8: =SUMIFS(Clean_Data!$I$2:$I$2203,Clean_Data!$AB$2:$AB$2203,"World|"&A8) -> 908.6 | F8: =SUMIFS(Clean_Data!$J$2:$J$2203,Clean_Data!$AB$2:$AB$2203,"World|"&A8) -> 2658.7 | G8: =SUMIFS(Clean_Data!$K$2:$K$2203,Clean_Data!$AB$2:$AB$2203,"World|"&A8) -> 4176.84 | H8: =SUMIFS(Clean_Data!$L$2:$L$2203,Clean_Data!$AB$2:$AB$2203,"World|"&A8) -> 575.16 | I8: =SUMIFS(Clean_Data!$M$2:$M$2203,Clean_Data!$AB$2:$AB$2203,"World|"&A8) -> 1268.14 | J8: =SUMIFS(Clean_Data!$N$2:$N$2203,Clean_Data!$AB$2:$AB$2203,"World|"&A8)+SUMIFS(Clean_Data!$O$2:$O$2203,Clean_Data!$AB$2:$AB$2203,"World|"&A8) -> 619.46 | K8: =(G8+H8+I8+J8)/B8 -> 0.25088713 | L8: =(H8+I8)/B8 -> 0.069651824 | M8: =C8/B8 -> 0.37911292 | N8: =(C8+D8+E8)/B8 -> 0.64864995 | O8: =B8/B7-1 -> 0.040228349 | P8: =H8/H7-1 -> 0.29351175
A9: 2019 | B9: =SUMIFS(Clean_Data!$F$2:$F$2203,Clean_Data!$AB$2:$AB$2203,"World|"&A9) -> 26832.42 | C9: =SUMIFS(Clean_Data!$G$2:$G$2203,Clean_Data!$AB$2:$AB$2203,"World|"&A9) -> 9826.39 | D9: =SUMIFS(Clean_Data!$H$2:$H$2203,Clean_Data!$AB$2:$AB$2203,"World|"&A9) -> 6401.31 | E9: =SUMIFS(Clean_Data!$I$2:$I$2203,Clean_Data!$AB$2:$AB$2203,"World|"&A9) -> 855.03 | F9: =SUMIFS(Clean_Data!$J$2:$J$2203,Clean_Data!$AB$2:$AB$2203,"World|"&A9) -> 2754.08 | G9: =SUMIFS(Clean_Data!$K$2:$K$2203,Clean_Data!$AB$2:$AB$2203,"World|"&A9) -> 4227.76 | H9: =SUMIFS(Clean_Data!$L$2:$L$2203,Clean_Data!$AB$2:$AB$2203,"World|"&A9) -> 697.94 | I9: =SUMIFS(Clean_Data!$M$2:$M$2203,Clean_Data!$AB$2:$AB$2203,"World|"&A9) -> 1420.96 | J9: =SUMIFS(Clean_Data!$N$2:$N$2203,Clean_Data!$AB$2:$AB$2203,"World|"&A9)+SUMIFS(Clean_Data!$O$2:$O$2203,Clean_Data!$AB$2:$AB$2203,"World|"&A9) -> 648.95 | K9: =(G9+H9+I9+J9)/B9 -> 0.26071484 | L9: =(H9+I9)/B9 -> 0.078967905 | M9: =C9/B9 -> 0.36621333 | N9: =(C9+D9+E9)/B9 -> 0.63664515 | O9: =B9/B8-1 -> 0.013902781 | P9: =H9/H8-1 -> 0.21347103
A10: 2020 | B10: =SUMIFS(Clean_Data!$F$2:$F$2203,Clean_Data!$AB$2:$AB$2203,"World|"&A10) -> 26723.369 | C10: =SUMIFS(Clean_Data!$G$2:$G$2203,Clean_Data!$AB$2:$AB$2203,"World|"&A10) -> 9437.05 | D10: =SUMIFS(Clean_Data!$H$2:$H$2203,Clean_Data!$AB$2:$AB$2203,"World|"&A10) -> 6382.94 | E10: =SUMIFS(Clean_Data!$I$2:$I$2203,Clean_Data!$AB$2:$AB$2203,"World|"&A10) -> 775.88 | F10: =SUMIFS(Clean_Data!$J$2:$J$2203,Clean_Data!$AB$2:$AB$2203,"World|"&A10) -> 2648.33 | G10: =SUMIFS(Clean_Data!$K$2:$K$2203,Clean_Data!$AB$2:$AB$2203,"World|"&A10) -> 4347.02 | H10: =SUMIFS(Clean_Data!$L$2:$L$2203,Clean_Data!$AB$2:$AB$2203,"World|"&A10) -> 853.39 | I10: =SUMIFS(Clean_Data!$M$2:$M$2203,Clean_Data!$AB$2:$AB$2203,"World|"&A10) -> 1591.47 | J10: =SUMIFS(Clean_Data!$N$2:$N$2203,Clean_Data!$AB$2:$AB$2203,"World|"&A10)+SUMIFS(Clean_Data!$O$2:$O$2203,Clean_Data!$AB$2:$AB$2203,"World|"&A10) -> 687.29 | K10: =(G10+H10+I10+J10)/B10 -> 0.27987377 | L10: =(H10+I10)/B10 -> 0.091487716 | M10: =C10/B10 -> 0.35313848 | N10: =(C10+D10+E10)/B10 -> 0.62102462 | O10: =B10/B9-1 -> -0.0040641508 | P10: =H10/H9-1 -> 0.22272688
A11: 2021 | B11: =SUMIFS(Clean_Data!$F$2:$F$2203,Clean_Data!$AB$2:$AB$2203,"World|"&A11) -> 28259.07 | C11: =SUMIFS(Clean_Data!$G$2:$G$2203,Clean_Data!$AB$2:$AB$2203,"World|"&A11) -> 10156.49 | D11: =SUMIFS(Clean_Data!$H$2:$H$2203,Clean_Data!$AB$2:$AB$2203,"World|"&A11) -> 6556.63 | E11: =SUMIFS(Clean_Data!$I$2:$I$2203,Clean_Data!$AB$2:$AB$2203,"World|"&A11) -> 842.25 | F11: =SUMIFS(Clean_Data!$J$2:$J$2203,Clean_Data!$AB$2:$AB$2203,"World|"&A11) -> 2762.44 | G11: =SUMIFS(Clean_Data!$K$2:$K$2203,Clean_Data!$AB$2:$AB$2203,"World|"&A11) -> 4288.7 | H11: =SUMIFS(Clean_Data!$L$2:$L$2203,Clean_Data!$AB$2:$AB$2203,"World|"&A11) -> 1053.99 | I11: =SUMIFS(Clean_Data!$M$2:$M$2203,Clean_Data!$AB$2:$AB$2203,"World|"&A11) -> 1856.94 | J11: =SUMIFS(Clean_Data!$N$2:$N$2203,Clean_Data!$AB$2:$AB$2203,"World|"&A11)+SUMIFS(Clean_Data!$O$2:$O$2203,Clean_Data!$AB$2:$AB$2203,"World|"&A11) -> 741.63 | K11: =(G11+H11+I11+J11)/B11 -> 0.28101633 | L11: =(H11+I11)/B11 -> 0.1030087 | M11: =C11/B11 -> 0.35940638 | N11: =(C11+D11+E11)/B11 -> 0.62122957 | O11: =B11/B10-1 -> 0.057466594 | P11: =H11/H10-1 -> 0.23506252
A12: 2022 | B12: =SUMIFS(Clean_Data!$F$2:$F$2203,Clean_Data!$AB$2:$AB$2203,"World|"&A12) -> 28917.76 | C12: =SUMIFS(Clean_Data!$G$2:$G$2203,Clean_Data!$AB$2:$AB$2203,"World|"&A12) -> 10240.44 | D12: =SUMIFS(Clean_Data!$H$2:$H$2203,Clean_Data!$AB$2:$AB$2203,"World|"&A12) -> 6628.27 | E12: =SUMIFS(Clean_Data!$I$2:$I$2203,Clean_Data!$AB$2:$AB$2203,"World|"&A12) -> 887.42 | F12: =SUMIFS(Clean_Data!$J$2:$J$2203,Clean_Data!$AB$2:$AB$2203,"World|"&A12) -> 2639.64 | G12: =SUMIFS(Clean_Data!$K$2:$K$2203,Clean_Data!$AB$2:$AB$2203,"World|"&A12) -> 4324.07 | H12: =SUMIFS(Clean_Data!$L$2:$L$2203,Clean_Data!$AB$2:$AB$2203,"World|"&A12) -> 1333.12 | I12: =SUMIFS(Clean_Data!$M$2:$M$2203,Clean_Data!$AB$2:$AB$2203,"World|"&A12) -> 2107.66 | J12: =SUMIFS(Clean_Data!$N$2:$N$2203,Clean_Data!$AB$2:$AB$2203,"World|"&A12)+SUMIFS(Clean_Data!$O$2:$O$2203,Clean_Data!$AB$2:$AB$2203,"World|"&A12) -> 757.14 | K12: =(G12+H12+I12+J12)/B12 -> 0.29469745 | L12: =(H12+I12)/B12 -> 0.11898501 | M12: =C12/B12 -> 0.35412286 | N12: =(C12+D12+E12)/B12 -> 0.61402163 | O12: =B12/B11-1 -> 0.023308977 | P12: =H12/H11-1 -> 0.26483173
A13: 2023 | B13: =SUMIFS(Clean_Data!$F$2:$F$2203,Clean_Data!$AB$2:$AB$2203,"World|"&A13) -> 29665.34 | C13: =SUMIFS(Clean_Data!$G$2:$G$2203,Clean_Data!$AB$2:$AB$2203,"World|"&A13) -> 10395.94 | D13: =SUMIFS(Clean_Data!$H$2:$H$2203,Clean_Data!$AB$2:$AB$2203,"World|"&A13) -> 6699.42 | E13: =SUMIFS(Clean_Data!$I$2:$I$2203,Clean_Data!$AB$2:$AB$2203,"World|"&A13) -> 876.79 | F13: =SUMIFS(Clean_Data!$J$2:$J$2203,Clean_Data!$AB$2:$AB$2203,"World|"&A13) -> 2697.74 | G13: =SUMIFS(Clean_Data!$K$2:$K$2203,Clean_Data!$AB$2:$AB$2203,"World|"&A13) -> 4240.11 | H13: =SUMIFS(Clean_Data!$L$2:$L$2203,Clean_Data!$AB$2:$AB$2203,"World|"&A13) -> 1664.14 | I13: =SUMIFS(Clean_Data!$M$2:$M$2203,Clean_Data!$AB$2:$AB$2203,"World|"&A13) -> 2319.18 | J13: =SUMIFS(Clean_Data!$N$2:$N$2203,Clean_Data!$AB$2:$AB$2203,"World|"&A13)+SUMIFS(Clean_Data!$O$2:$O$2203,Clean_Data!$AB$2:$AB$2203,"World|"&A13) -> 772.02 | K13: =(G13+H13+I13+J13)/B13 -> 0.30323098 | L13: =(H13+I13)/B13 -> 0.13427522 | M13: =C13/B13 -> 0.35044062 | N13: =(C13+D13+E13)/B13 -> 0.6058299 | O13: =B13/B12-1 -> 0.025851933 | P13: =H13/H12-1 -> 0.24830473
A14: 2024 | B14: =SUMIFS(Clean_Data!$F$2:$F$2203,Clean_Data!$AB$2:$AB$2203,"World|"&A14) -> 30930.23 | C14: =SUMIFS(Clean_Data!$G$2:$G$2203,Clean_Data!$AB$2:$AB$2203,"World|"&A14) -> 10538.94 | D14: =SUMIFS(Clean_Data!$H$2:$H$2203,Clean_Data!$AB$2:$AB$2203,"World|"&A14) -> 6882.73 | E14: =SUMIFS(Clean_Data!$I$2:$I$2203,Clean_Data!$AB$2:$AB$2203,"World|"&A14) -> 853.84 | F14: =SUMIFS(Clean_Data!$J$2:$J$2203,Clean_Data!$AB$2:$AB$2203,"World|"&A14) -> 2777.11 | G14: =SUMIFS(Clean_Data!$K$2:$K$2203,Clean_Data!$AB$2:$AB$2203,"World|"&A14) -> 4433.65 | H14: =SUMIFS(Clean_Data!$L$2:$L$2203,Clean_Data!$AB$2:$AB$2203,"World|"&A14) -> 2142.65 | I14: =SUMIFS(Clean_Data!$M$2:$M$2203,Clean_Data!$AB$2:$AB$2203,"World|"&A14) -> 2509.5 | J14: =SUMIFS(Clean_Data!$N$2:$N$2203,Clean_Data!$AB$2:$AB$2203,"World|"&A14)+SUMIFS(Clean_Data!$O$2:$O$2203,Clean_Data!$AB$2:$AB$2203,"World|"&A14) -> 791.81 | K14: =(G14+H14+I14+J14)/B14 -> 0.31935133 | L14: =(H14+I14)/B14 -> 0.15040787 | M14: =C14/B14 -> 0.34073267 | N14: =(C14+D14+E14)/B14 -> 0.5908624 | O14: =B14/B13-1 -> 0.042638648 | P14: =H14/H13-1 -> 0.28754191
A15: 2025 | B15: =SUMIFS(Clean_Data!$F$2:$F$2203,Clean_Data!$AB$2:$AB$2203,"World|"&A15) -> 31772.35 | C15: =SUMIFS(Clean_Data!$G$2:$G$2203,Clean_Data!$AB$2:$AB$2203,"World|"&A15) -> 10471.53 | D15: =SUMIFS(Clean_Data!$H$2:$H$2203,Clean_Data!$AB$2:$AB$2203,"World|"&A15) -> 6921.14 | E15: =SUMIFS(Clean_Data!$I$2:$I$2203,Clean_Data!$AB$2:$AB$2203,"World|"&A15) -> 841.62 | F15: =SUMIFS(Clean_Data!$J$2:$J$2203,Clean_Data!$AB$2:$AB$2203,"World|"&A15) -> 2811.57 | G15: =SUMIFS(Clean_Data!$K$2:$K$2203,Clean_Data!$AB$2:$AB$2203,"World|"&A15) -> 4434.97 | H15: =SUMIFS(Clean_Data!$L$2:$L$2203,Clean_Data!$AB$2:$AB$2203,"World|"&A15) -> 2778.64 | I15: =SUMIFS(Clean_Data!$M$2:$M$2203,Clean_Data!$AB$2:$AB$2203,"World|"&A15) -> 2713.14 | J15: =SUMIFS(Clean_Data!$N$2:$N$2203,Clean_Data!$AB$2:$AB$2203,"World|"&A15)+SUMIFS(Clean_Data!$O$2:$O$2203,Clean_Data!$AB$2:$AB$2203,"World|"&A15) -> 799.74 | K15: =(G15+H15+I15+J15)/B15 -> 0.33760455 | L15: =(H15+I15)/B15 -> 0.17284777 | M15: =C15/B15 -> 0.32957996 | N15: =(C15+D15+E15)/B15 -> 0.57390435 | O15: =B15/B14-1 -> 0.027226438 | P15: =H15/H14-1 -> 0.29682403
A17: Change 2015 → 2025 | B17: =B15-B5 -> 7770 | C17: =C15-C5 -> 1187.92 | D17: =D15-D5 -> 1381.26 | E17: =E15-E5 -> -291.67 | F17: =F15-F5 -> 278.64 | G17: =G15-G5 -> 552.84 | H17: =H15-H5 -> 2522.63 | I17: =I15-I5 -> 1883.51 | J17: =J15-J5 -> 254.87 | K17: =(K15-K5)*100 -> 10.793371 | L17: =(L15-L5)*100 -> 12.76172 | M17: =(M15-M5)*100 -> -5.7199246 | N17: =(N15-N5)*100 -> -9.0896384
A18: Solar output multiple (2025 ÷ 2015) | H18: =H15/H5 -> 10.853639
A19: Share of new demand met by solar + wind | H19: =(H17+I17)/B17 -> 0.56707079

Sheet Rankings
A1: Country Rankings
A2: ="Analysis year "&Inputs!$B$6&" · countries generating ≥ "&Inputs!$B$7&" TWh · solar+wind gain measured from "&Inputs!$B$5 -> Analysis year 2024 · countries generating ≥ 20 TWh · solar+wind gain measured from 2015
A4: Top 15 – highest renewable share | G4: Top 15 – fastest solar + wind gain
A5: # | B5: Country | C5: RE Share | D5: Generation (TWh) | E5: Change vs base (pp) | G5: # | H5: Country | I5: Gain (pp) | J5: S+W Share Base | K5: S+W Share Analysis
A6: 1 | B6: =IF(LARGE(Country_Summary!$N$6:$N$217,A6)>-1,INDEX(Country_Summary!$A$6:$A$217,MATCH(LARGE(Country_Summary!$N$6:$N$217,A6),Country_Summary!$N$6:$N$217,0)),"") -> Paraguay | C6: =IF(B6="","",INDEX(Country_Summary!$F$6:$F$217,MATCH(LARGE(Country_Summary!$N$6:$N$217,A6),Country_Summary!$N$6:$N$217,0))) -> 1 | D6: =IF(B6="","",INDEX(Country_Summary!$C$6:$C$217,MATCH(LARGE(Country_Summary!$N$6:$N$217,A6),Country_Summary!$N$6:$N$217,0))) -> 42.41 | E6: =IF(B6="","",INDEX(Country_Summary!$G$6:$G$217,MATCH(LARGE(Country_Summary!$N$6:$N$217,A6),Country_Summary!$N$6:$N$217,0))) -> 0 | G6: 1 | H6: =IF(LARGE(Country_Summary!$O$6:$O$217,G6)>-1,INDEX(Country_Summary!$A$6:$A$217,MATCH(LARGE(Country_Summary!$O$6:$O$217,G6),Country_Summary!$O$6:$O$217,0)),"") -> Netherlands | I6: =IF(H6="","",INDEX(Country_Summary!$J$6:$J$217,MATCH(LARGE(Country_Summary!$O$6:$O$217,G6),Country_Summary!$O$6:$O$217,0))) -> 37.259908 | J6: =IF(H6="","",INDEX(Country_Summary!$H$6:$H$217,MATCH(LARGE(Country_Summary!$O$6:$O$217,G6),Country_Summary!$O$6:$O$217,0))) -> 0.079456831 | K6: =IF(H6="","",INDEX(Country_Summary!$I$6:$I$217,MATCH(LARGE(Country_Summary!$O$6:$O$217,G6),Country_Summary!$O$6:$O$217,0))) -> 0.45205591
A7: 2 | B7: =IF(LARGE(Country_Summary!$N$6:$N$217,A7)>-1,INDEX(Country_Summary!$A$6:$A$217,MATCH(LARGE(Country_Summary!$N$6:$N$217,A7),Country_Summary!$N$6:$N$217,0)),"") -> Ethiopia | C7: =IF(B7="","",INDEX(Country_Summary!$F$6:$F$217,MATCH(LARGE(Country_Summary!$N$6:$N$217,A7),Country_Summary!$N$6:$N$217,0))) -> 1 | D7: =IF(B7="","",INDEX(Country_Summary!$C$6:$C$217,MATCH(LARGE(Country_Summary!$N$6:$N$217,A7),Country_Summary!$N$6:$N$217,0))) -> 25.2 | E7: =IF(B7="","",INDEX(Country_Summary!$G$6:$G$217,MATCH(LARGE(Country_Summary!$N$6:$N$217,A7),Country_Summary!$N$6:$N$217,0))) -> 0 | G7: 2 | H7: =IF(LARGE(Country_Summary!$O$6:$O$217,G7)>-1,INDEX(Country_Summary!$A$6:$A$217,MATCH(LARGE(Country_Summary!$O$6:$O$217,G7),Country_Summary!$O$6:$O$217,0)),"") -> Chile | I7: =IF(H7="","",INDEX(Country_Summary!$J$6:$J$217,MATCH(LARGE(Country_Summary!$O$6:$O$217,G7),Country_Summary!$O$6:$O$217,0))) -> 30.079987 | J7: =IF(H7="","",INDEX(Country_Summary!$H$6:$H$217,MATCH(LARGE(Country_Summary!$O$6:$O$217,G7),Country_Summary!$O$6:$O$217,0))) -> 0.044720331 | K7: =IF(H7="","",INDEX(Country_Summary!$I$6:$I$217,MATCH(LARGE(Country_Summary!$O$6:$O$217,G7),Country_Summary!$O$6:$O$217,0))) -> 0.3455202
A8: 3 | B8: =IF(LARGE(Country_Summary!$N$6:$N$217,A8)>-1,INDEX(Country_Summary!$A$6:$A$217,MATCH(LARGE(Country_Summary!$N$6:$N$217,A8),Country_Summary!$N$6:$N$217,0)),"") -> Norway | C8: =IF(B8="","",INDEX(Country_Summary!$F$6:$F$217,MATCH(LARGE(Country_Summary!$N$6:$N$217,A8),Country_Summary!$N$6:$N$217,0))) -> 0.98606072 | D8: =IF(B8="","",INDEX(Country_Summary!$C$6:$C$217,MATCH(LARGE(Country_Summary!$N$6:$N$217,A8),Country_Summary!$N$6:$N$217,0))) -> 157.11 | E8: =IF(B8="","",INDEX(Country_Summary!$G$6:$G$217,MATCH(LARGE(Country_Summary!$N$6:$N$217,A8),Country_Summary!$N$6:$N$217,0))) -> 0.65502323 | G8: 3 | H8: =IF(LARGE(Country_Summary!$O$6:$O$217,G8)>-1,INDEX(Country_Summary!$A$6:$A$217,MATCH(LARGE(Country_Summary!$O$6:$O$217,G8),Country_Summary!$O$6:$O$217,0)),"") -> Greece | I8: =IF(H8="","",INDEX(Country_Summary!$J$6:$J$217,MATCH(LARGE(Country_Summary!$O$6:$O$217,G8),Country_Summary!$O$6:$O$217,0))) -> 25.023865 | J8: =IF(H8="","",INDEX(Country_Summary!$H$6:$H$217,MATCH(LARGE(Country_Summary!$O$6:$O$217,G8),Country_Summary!$O$6:$O$217,0))) -> 0.1668952 | K8: =IF(H8="","",INDEX(Country_Summary!$I$6:$I$217,MATCH(LARGE(Country_Summary!$O$6:$O$217,G8),Country_Summary!$O$6:$O$217,0))) -> 0.41713385
A9: 4 | B9: =IF(LARGE(Country_Summary!$N$6:$N$217,A9)>-1,INDEX(Country_Summary!$A$6:$A$217,MATCH(LARGE(Country_Summary!$N$6:$N$217,A9),Country_Summary!$N$6:$N$217,0)),"") -> Tajikistan | C9: =IF(B9="","",INDEX(Country_Summary!$F$6:$F$217,MATCH(LARGE(Country_Summary!$N$6:$N$217,A9),Country_Summary!$N$6:$N$217,0))) -> 0.94594595 | D9: =IF(B9="","",INDEX(Country_Summary!$C$6:$C$217,MATCH(LARGE(Country_Summary!$N$6:$N$217,A9),Country_Summary!$N$6:$N$217,0))) -> 22.2 | E9: =IF(B9="","",INDEX(Country_Summary!$G$6:$G$217,MATCH(LARGE(Country_Summary!$N$6:$N$217,A9),Country_Summary!$N$6:$N$217,0))) -> -4.4730045 | G9: 4 | H9: =IF(LARGE(Country_Summary!$O$6:$O$217,G9)>-1,INDEX(Country_Summary!$A$6:$A$217,MATCH(LARGE(Country_Summary!$O$6:$O$217,G9),Country_Summary!$O$6:$O$217,0)),"") -> Germany | I9: =IF(H9="","",INDEX(Country_Summary!$J$6:$J$217,MATCH(LARGE(Country_Summary!$O$6:$O$217,G9),Country_Summary!$O$6:$O$217,0))) -> 24.923869 | J9: =IF(H9="","",INDEX(Country_Summary!$H$6:$H$217,MATCH(LARGE(Country_Summary!$O$6:$O$217,G9),Country_Summary!$O$6:$O$217,0))) -> 0.18570959 | K9: =IF(H9="","",INDEX(Country_Summary!$I$6:$I$217,MATCH(LARGE(Country_Summary!$O$6:$O$217,G9),Country_Summary!$O$6:$O$217,0))) -> 0.43494829
A10: 5 | B10: =IF(LARGE(Country_Summary!$N$6:$N$217,A10)>-1,INDEX(Country_Summary!$A$6:$A$217,MATCH(LARGE(Country_Summary!$N$6:$N$217,A10),Country_Summary!$N$6:$N$217,0)),"") -> Venezuela | C10: =IF(B10="","",INDEX(Country_Summary!$F$6:$F$217,MATCH(LARGE(Country_Summary!$N$6:$N$217,A10),Country_Summary!$N$6:$N$217,0))) -> 0.91139398 | D10: =IF(B10="","",INDEX(Country_Summary!$C$6:$C$217,MATCH(LARGE(Country_Summary!$N$6:$N$217,A10),Country_Summary!$N$6:$N$217,0))) -> 80.13 | E10: =IF(B10="","",INDEX(Country_Summary!$G$6:$G$217,MATCH(LARGE(Country_Summary!$N$6:$N$217,A10),Country_Summary!$N$6:$N$217,0))) -> 32.325095 | G10: 5 | H10: =IF(LARGE(Country_Summary!$O$6:$O$217,G10)>-1,INDEX(Country_Summary!$A$6:$A$217,MATCH(LARGE(Country_Summary!$O$6:$O$217,G10),Country_Summary!$O$6:$O$217,0)),"") -> Hungary | I10: =IF(H10="","",INDEX(Country_Summary!$J$6:$J$217,MATCH(LARGE(Country_Summary!$O$6:$O$217,G10),Country_Summary!$O$6:$O$217,0))) -> 23.289751 | J10: =IF(H10="","",INDEX(Country_Summary!$H$6:$H$217,MATCH(LARGE(Country_Summary!$O$6:$O$217,G10),Country_Summary!$O$6:$O$217,0))) -> 0.027365645 | K10: =IF(H10="","",INDEX(Country_Summary!$I$6:$I$217,MATCH(LARGE(Country_Summary!$O$6:$O$217,G10),Country_Summary!$O$6:$O$217,0))) -> 0.26026316
A11: 6 | B11: =IF(LARGE(Country_Summary!$N$6:$N$217,A11)>-1,INDEX(Country_Summary!$A$6:$A$217,MATCH(LARGE(Country_Summary!$N$6:$N$217,A11),Country_Summary!$N$6:$N$217,0)),"") -> Denmark | C11: =IF(B11="","",INDEX(Country_Summary!$F$6:$F$217,MATCH(LARGE(Country_Summary!$N$6:$N$217,A11),Country_Summary!$N$6:$N$217,0))) -> 0.8918996 | D11: =IF(B11="","",INDEX(Country_Summary!$C$6:$C$217,MATCH(LARGE(Country_Summary!$N$6:$N$217,A11),Country_Summary!$N$6:$N$217,0))) -> 35.06 | E11: =IF(B11="","",INDEX(Country_Summary!$G$6:$G$217,MATCH(LARGE(Country_Summary!$N$6:$N$217,A11),Country_Summary!$N$6:$N$217,0))) -> 23.415116 | G11: 6 | H11: =IF(LARGE(Country_Summary!$O$6:$O$217,G11)>-1,INDEX(Country_Summary!$A$6:$A$217,MATCH(LARGE(Country_Summary!$O$6:$O$217,G11),Country_Summary!$O$6:$O$217,0)),"") -> Jordan | I11: =IF(H11="","",INDEX(Country_Summary!$J$6:$J$217,MATCH(LARGE(Country_Summary!$O$6:$O$217,G11),Country_Summary!$O$6:$O$217,0))) -> 23.1047 | J11: =IF(H11="","",INDEX(Country_Summary!$H$6:$H$217,MATCH(LARGE(Country_Summary!$O$6:$O$217,G11),Country_Summary!$O$6:$O$217,0))) -> 0.0089192025 | K11: =IF(H11="","",INDEX(Country_Summary!$I$6:$I$217,MATCH(LARGE(Country_Summary!$O$6:$O$217,G11),Country_Summary!$O$6:$O$217,0))) -> 0.2399662
A12: 7 | B12: =IF(LARGE(Country_Summary!$N$6:$N$217,A12)>-1,INDEX(Country_Summary!$A$6:$A$217,MATCH(LARGE(Country_Summary!$N$6:$N$217,A12),Country_Summary!$N$6:$N$217,0)),"") -> Brazil | C12: =IF(B12="","",INDEX(Country_Summary!$F$6:$F$217,MATCH(LARGE(Country_Summary!$N$6:$N$217,A12),Country_Summary!$N$6:$N$217,0))) -> 0.87333047 | D12: =IF(B12="","",INDEX(Country_Summary!$C$6:$C$217,MATCH(LARGE(Country_Summary!$N$6:$N$217,A12),Country_Summary!$N$6:$N$217,0))) -> 745.72 | E12: =IF(B12="","",INDEX(Country_Summary!$G$6:$G$217,MATCH(LARGE(Country_Summary!$N$6:$N$217,A12),Country_Summary!$N$6:$N$217,0))) -> 13.125346 | G12: 7 | H12: =IF(LARGE(Country_Summary!$O$6:$O$217,G12)>-1,INDEX(Country_Summary!$A$6:$A$217,MATCH(LARGE(Country_Summary!$O$6:$O$217,G12),Country_Summary!$O$6:$O$217,0)),"") -> Finland | I12: =IF(H12="","",INDEX(Country_Summary!$J$6:$J$217,MATCH(LARGE(Country_Summary!$O$6:$O$217,G12),Country_Summary!$O$6:$O$217,0))) -> 22.537329 | J12: =IF(H12="","",INDEX(Country_Summary!$H$6:$H$217,MATCH(LARGE(Country_Summary!$O$6:$O$217,G12),Country_Summary!$O$6:$O$217,0))) -> 0.034105815 | K12: =IF(H12="","",INDEX(Country_Summary!$I$6:$I$217,MATCH(LARGE(Country_Summary!$O$6:$O$217,G12),Country_Summary!$O$6:$O$217,0))) -> 0.2594791
A13: 8 | B13: =IF(LARGE(Country_Summary!$N$6:$N$217,A13)>-1,INDEX(Country_Summary!$A$6:$A$217,MATCH(LARGE(Country_Summary!$N$6:$N$217,A13),Country_Summary!$N$6:$N$217,0)),"") -> Austria | C13: =IF(B13="","",INDEX(Country_Summary!$F$6:$F$217,MATCH(LARGE(Country_Summary!$N$6:$N$217,A13),Country_Summary!$N$6:$N$217,0))) -> 0.86224035 | D13: =IF(B13="","",INDEX(Country_Summary!$C$6:$C$217,MATCH(LARGE(Country_Summary!$N$6:$N$217,A13),Country_Summary!$N$6:$N$217,0))) -> 78.47 | E13: =IF(B13="","",INDEX(Country_Summary!$G$6:$G$217,MATCH(LARGE(Country_Summary!$N$6:$N$217,A13),Country_Summary!$N$6:$N$217,0))) -> 9.1926329 | G13: 8 | H13: =IF(LARGE(Country_Summary!$O$6:$O$217,G13)>-1,INDEX(Country_Summary!$A$6:$A$217,MATCH(LARGE(Country_Summary!$O$6:$O$217,G13),Country_Summary!$O$6:$O$217,0)),"") -> Australia | I13: =IF(H13="","",INDEX(Country_Summary!$J$6:$J$217,MATCH(LARGE(Country_Summary!$O$6:$O$217,G13),Country_Summary!$O$6:$O$217,0))) -> 22.353788 | J13: =IF(H13="","",INDEX(Country_Summary!$H$6:$H$217,MATCH(LARGE(Country_Summary!$O$6:$O$217,G13),Country_Summary!$O$6:$O$217,0))) -> 0.070987047 | K13: =IF(H13="","",INDEX(Country_Summary!$I$6:$I$217,MATCH(LARGE(Country_Summary!$O$6:$O$217,G13),Country_Summary!$O$6:$O$217,0))) -> 0.29452493
A14: 9 | B14: =IF(LARGE(Country_Summary!$N$6:$N$217,A14)>-1,INDEX(Country_Summary!$A$6:$A$217,MATCH(LARGE(Country_Summary!$N$6:$N$217,A14),Country_Summary!$N$6:$N$217,0)),"") -> New Zealand | C14: =IF(B14="","",INDEX(Country_Summary!$F$6:$F$217,MATCH(LARGE(Country_Summary!$N$6:$N$217,A14),Country_Summary!$N$6:$N$217,0))) -> 0.85980459 | D14: =IF(B14="","",INDEX(Country_Summary!$C$6:$C$217,MATCH(LARGE(Country_Summary!$N$6:$N$217,A14),Country_Summary!$N$6:$N$217,0))) -> 44.01 | E14: =IF(B14="","",INDEX(Country_Summary!$G$6:$G$217,MATCH(LARGE(Country_Summary!$N$6:$N$217,A14),Country_Summary!$N$6:$N$217,0))) -> 5.9024236 | G14: 9 | H14: =IF(LARGE(Country_Summary!$O$6:$O$217,G14)>-1,INDEX(Country_Summary!$A$6:$A$217,MATCH(LARGE(Country_Summary!$O$6:$O$217,G14),Country_Summary!$O$6:$O$217,0)),"") -> Portugal | I14: =IF(H14="","",INDEX(Country_Summary!$J$6:$J$217,MATCH(LARGE(Country_Summary!$O$6:$O$217,G14),Country_Summary!$O$6:$O$217,0))) -> 21.088143 | J14: =IF(H14="","",INDEX(Country_Summary!$H$6:$H$217,MATCH(LARGE(Country_Summary!$O$6:$O$217,G14),Country_Summary!$O$6:$O$217,0))) -> 0.24247165 | K14: =IF(H14="","",INDEX(Country_Summary!$I$6:$I$217,MATCH(LARGE(Country_Summary!$O$6:$O$217,G14),Country_Summary!$O$6:$O$217,0))) -> 0.45335308
A15: 10 | B15: =IF(LARGE(Country_Summary!$N$6:$N$217,A15)>-1,INDEX(Country_Summary!$A$6:$A$217,MATCH(LARGE(Country_Summary!$N$6:$N$217,A15),Country_Summary!$N$6:$N$217,0)),"") -> Portugal | C15: =IF(B15="","",INDEX(Country_Summary!$F$6:$F$217,MATCH(LARGE(Country_Summary!$N$6:$N$217,A15),Country_Summary!$N$6:$N$217,0))) -> 0.85191453 | D15: =IF(B15="","",INDEX(Country_Summary!$C$6:$C$217,MATCH(LARGE(Country_Summary!$N$6:$N$217,A15),Country_Summary!$N$6:$N$217,0))) -> 47.27 | E15: =IF(B15="","",INDEX(Country_Summary!$G$6:$G$217,MATCH(LARGE(Country_Summary!$N$6:$N$217,A15),Country_Summary!$N$6:$N$217,0))) -> 37.557507 | G15: 10 | H15: =IF(LARGE(Country_Summary!$O$6:$O$217,G15)>-1,INDEX(Country_Summary!$A$6:$A$217,MATCH(LARGE(Country_Summary!$O$6:$O$217,G15),Country_Summary!$O$6:$O$217,0)),"") -> United Kingdom | I15: =IF(H15="","",INDEX(Country_Summary!$J$6:$J$217,MATCH(LARGE(Country_Summary!$O$6:$O$217,G15),Country_Summary!$O$6:$O$217,0))) -> 20.406542 | J15: =IF(H15="","",INDEX(Country_Summary!$H$6:$H$217,MATCH(LARGE(Country_Summary!$O$6:$O$217,G15),Country_Summary!$O$6:$O$217,0))) -> 0.14105704 | K15: =IF(H15="","",INDEX(Country_Summary!$I$6:$I$217,MATCH(LARGE(Country_Summary!$O$6:$O$217,G15),Country_Summary!$O$6:$O$217,0))) -> 0.34512247
A16: 11 | B16: =IF(LARGE(Country_Summary!$N$6:$N$217,A16)>-1,INDEX(Country_Summary!$A$6:$A$217,MATCH(LARGE(Country_Summary!$N$6:$N$217,A16),Country_Summary!$N$6:$N$217,0)),"") -> Laos | C16: =IF(B16="","",INDEX(Country_Summary!$F$6:$F$217,MATCH(LARGE(Country_Summary!$N$6:$N$217,A16),Country_Summary!$N$6:$N$217,0))) -> 0.76715733 | D16: =IF(B16="","",INDEX(Country_Summary!$C$6:$C$217,MATCH(LARGE(Country_Summary!$N$6:$N$217,A16),Country_Summary!$N$6:$N$217,0))) -> 52.31 | E16: =IF(B16="","",INDEX(Country_Summary!$G$6:$G$217,MATCH(LARGE(Country_Summary!$N$6:$N$217,A16),Country_Summary!$N$6:$N$217,0))) -> -9.2991184 | G16: 11 | H16: =IF(LARGE(Country_Summary!$O$6:$O$217,G16)>-1,INDEX(Country_Summary!$A$6:$A$217,MATCH(LARGE(Country_Summary!$O$6:$O$217,G16),Country_Summary!$O$6:$O$217,0)),"") -> Brazil | I16: =IF(H16="","",INDEX(Country_Summary!$J$6:$J$217,MATCH(LARGE(Country_Summary!$O$6:$O$217,G16),Country_Summary!$O$6:$O$217,0))) -> 20.380462 | J16: =IF(H16="","",INDEX(Country_Summary!$H$6:$H$217,MATCH(LARGE(Country_Summary!$O$6:$O$217,G16),Country_Summary!$O$6:$O$217,0))) -> 0.037318055 | K16: =IF(H16="","",INDEX(Country_Summary!$I$6:$I$217,MATCH(LARGE(Country_Summary!$O$6:$O$217,G16),Country_Summary!$O$6:$O$217,0))) -> 0.24112267
A17: 12 | B17: =IF(LARGE(Country_Summary!$N$6:$N$217,A17)>-1,INDEX(Country_Summary!$A$6:$A$217,MATCH(LARGE(Country_Summary!$N$6:$N$217,A17),Country_Summary!$N$6:$N$217,0)),"") -> Ecuador | C17: =IF(B17="","",INDEX(Country_Summary!$F$6:$F$217,MATCH(LARGE(Country_Summary!$N$6:$N$217,A17),Country_Summary!$N$6:$N$217,0))) -> 0.72443356 | D17: =IF(B17="","",INDEX(Country_Summary!$C$6:$C$217,MATCH(LARGE(Country_Summary!$N$6:$N$217,A17),Country_Summary!$N$6:$N$217,0))) -> 32.66 | E17: =IF(B17="","",INDEX(Country_Summary!$G$6:$G$217,MATCH(LARGE(Country_Summary!$N$6:$N$217,A17),Country_Summary!$N$6:$N$217,0))) -> 21.339988 | G17: 12 | H17: =IF(LARGE(Country_Summary!$O$6:$O$217,G17)>-1,INDEX(Country_Summary!$A$6:$A$217,MATCH(LARGE(Country_Summary!$O$6:$O$217,G17),Country_Summary!$O$6:$O$217,0)),"") -> Spain | I17: =IF(H17="","",INDEX(Country_Summary!$J$6:$J$217,MATCH(LARGE(Country_Summary!$O$6:$O$217,G17),Country_Summary!$O$6:$O$217,0))) -> 20.093486 | J17: =IF(H17="","",INDEX(Country_Summary!$H$6:$H$217,MATCH(LARGE(Country_Summary!$O$6:$O$217,G17),Country_Summary!$O$6:$O$217,0))) -> 0.22794675 | K17: =IF(H17="","",INDEX(Country_Summary!$I$6:$I$217,MATCH(LARGE(Country_Summary!$O$6:$O$217,G17),Country_Summary!$O$6:$O$217,0))) -> 0.42888161
... A20: 15 | B20: =IF(LARGE(Country_Summary!$N$6:$N$217,A20)>-1,INDEX(Country_Summary!$A$6:$A$217,MATCH(LARGE(Country_Summary!$N$6:$N$217,A20),Country_Summary!$N$6:$N$217,0)),"") -> Switzerland | C20: =IF(B20="","",INDEX(Country_Summary!$F$6:$F$217,MATCH(LARGE(Country_Summary!$N$6:$N$217,A20),Country_Summary!$N$6:$N$217,0))) -> 0.67449279 | D20: =IF(B20="","",INDEX(Country_Summary!$C$6:$C$217,MATCH(LARGE(Country_Summary!$N$6:$N$217,A20),Country_Summary!$N$6:$N$217,0))) -> 78.37 | E20: =IF(B20="","",INDEX(Country_Summary!$G$6:$G$217,MATCH(LARGE(Country_Summary!$N$6:$N$217,A20),Country_Summary!$N$6:$N$217,0))) -> 5.2122577 | G20: 15 | H20: =IF(LARGE(Country_Summary!$O$6:$O$217,G20)>-1,INDEX(Country_Summary!$A$6:$A$217,MATCH(LARGE(Country_Summary!$O$6:$O$217,G20),Country_Summary!$O$6:$O$217,0)),"") -> Belgium | I20: =IF(H20="","",INDEX(Country_Summary!$J$6:$J$217,MATCH(LARGE(Country_Summary!$O$6:$O$217,G20),Country_Summary!$O$6:$O$217,0))) -> 17.147814 | J20: =IF(H20="","",INDEX(Country_Summary!$H$6:$H$217,MATCH(LARGE(Country_Summary!$O$6:$O$217,G20),Country_Summary!$O$6:$O$217,0))) -> 0.12611428 | K20: =IF(H20="","",INDEX(Country_Summary!$I$6:$I$217,MATCH(LARGE(Country_Summary!$O$6:$O$217,G20),Country_Summary!$O$6:$O$217,0))) -> 0.29759242
A22: Top 10 – most coal-dependent
A23: # | B23: Country | C23: Coal Share | D23: Generation (TWh) | E23: Carbon Int. (g/kWh) | G23: Where does India rank?
